<?xml version="1.0"?>
<robot name="holo" xmlns:xacro="http://ros.org/wiki/xacro">

  <material name="black"><color rgba="0.15 0.15 0.15 1.0"/></material>
  <material name="dark_grey"><color rgba="0.2 0.2 0.2 1.0"/></material>
  <material name="light_grey"><color rgba="0.4 0.4 0.4 1.0"/></material>

  <link name="base_footprint"></link>
  <joint name="base_link_joint" type="fixed">
    <origin xyz="0 0 0.05" rpy="0 0 0" />
    <parent link="base_footprint"/>
    <child link="base_link"/>
  </joint>
  
  <link name="base_link">
    <inertial>
      <origin
        xyz="0.000663062226349709 0.000901948709669016 0.0518310748808297"
        rpy="0 0 0" />
      <mass value="24.5056773765118" />
      <inertia
        ixx="0.522950097950444"
        ixy="4.94215553635564E-15"
        ixz="3.83933411877259E-15"
        iyy="0.522677188378826"
        iyz="3.03157454020582E-18"
        izz="1.0078793684858" />
    </inertial>
    <visual>
      <origin xyz="0 0 0" rpy="0 0 0" />
      <geometry>
        <mesh filename="package://non_description/meshes/base_link.STL" />
      </geometry>
      <material name="light_grey"/>
    </visual>
    <collision>
      <origin xyz="0 0 0" rpy="0 0 0" />
      <geometry>
        <mesh filename="package://non_description/meshes/base_link.STL" />
      </geometry>
    </collision>
  </link>
  <link name="left_wheel_link">
    <inertial>
      <origin xyz="-1.11022302462516E-16 -0.0099999999999999 0" rpy="0 0 0" />
      <mass value="0.172530421663568" />
      <inertial>
      <origin xyz="0 5.5511E-17 2.7756E-17" rpy="0 0 0" />
      <mass value="0.23316" />
      <inertia
        ixx="0.00023384"
        ixy="1.8449E-18"
        ixz="5.5653E-21"
        iyy="0.00044999"
        iyz="-2.6244E-20"
        izz="0.00023384" />
    </inertial>
    <visual>
      <origin xyz="0 0 0" rpy="0 0 0" />
      <geometry>
        <mesh filename="package://non_description/meshes/left_wheel_link.STL" />
      </geometry>
      <material name="dark_grey"/>
    </visual>
    <collision>
      <origin xyz="0 0 0" rpy="0 0 0" />
      <geometry>
        <mesh filename="package://non_description/meshes/left_wheel_link.STL" />
      </geometry>
    </collision>
  </link>
  <joint name="left_wheel_joint" type="continuous">
    <origin xyz="0.00068317 0.27589 0.029895" rpy="0 0 0" />
    <parent link="base_link" />
    <child link="left_wheel_link" />
    <axis xyz="0 -1 0" />
  </joint>
  <link name="right_wheel_link">
    <inertial>
      <origin xyz="1.1102E-16 -5.5511E-17 1.3878E-17" rpy="0 0 0" />
      <mass value="0.23316" />
      <inertia
        ixx="0.00023384"
        ixy="1.8559E-18"
        ixz="-4.9188E-21"
        iyy="0.00044999"
        iyz="-2.8705E-20"
        izz="0.00023384" />
    </inertial>
    <visual>
      <origin xyz="0 0 0" rpy="0 0 0" />
      <geometry>
        <mesh filename="package://non_description/meshes/right_wheel_link.STL" />
      </geometry>
      <material name="dark_grey"/>
    </visual>
    <collision>
      <origin xyz="0 0 0" rpy="0 0 0" />
      <geometry>
        <mesh filename="package://non_description/meshes/right_wheel_link.STL" />
      </geometry>
    </collision>
  </link>
  <joint name="right_wheel_joint" type="continuous">
    <origin xyz="0.00068317 -0.27411 0.029895" rpy="0 0 0" />
    <parent link="base_link" />
    <child link="right_wheel_link" />
    <axis
      xyz="0 -1 0" />
  </joint>
  <gazebo>
    <!--<plugin name="gazebo_ros_control" filename="libgazebo_ros_control.so">
      <robotNamespace>/</robotNamespace>
    </plugin>-->
  
    <plugin filename="libgazebo_ros_diff_drive.so" name="non_controller">
    <!-- Plugin update rate in Hz -->
    <updateRate>100</updateRate>

    <!-- Name of left joint, defaults to `left_joint` -->
    <leftJoint>left_wheel_joint</leftJoint>

    <!-- Name of right joint, defaults to `right_joint` -->
    <rightJoint>right_wheel_joint</rightJoint>

    <!-- The distance from the center of one wheel to the other, in meters, defaults to 0.34 m -->
    <wheelSeparation>0.55</wheelSeparation>

    <!-- Diameter of the wheels, in meters, defaults to 0.15 m -->
    <wheelDiameter>0.12</wheelDiameter>

    <!-- Wheel acceleration, in rad/s^2, defaults to 0.0 rad/s^2 -->
    <wheelAcceleration>0.0</wheelAcceleration>

    <!-- Maximum torque which the wheels can produce, in Nm, defaults to 5 Nm -->
    <wheelTorque>5</wheelTorque>

    <!-- Topic to receive geometry_msgs/Twist message commands, defaults to `cmd_vel` -->
    <commandTopic>cmd_vel</commandTopic>

    <!-- Topic to publish nav_msgs/Odometry messages, defaults to `odom` -->
    <odometryTopic>odom</odometryTopic>

    <!-- Odometry frame, defaults to `odom` -->
    <odometryFrame>odom</odometryFrame>

    <!-- Robot frame to calculate odometry from, defaults to `base_footprint` -->
    <robotBaseFrame>base_footprint</robotBaseFrame>

    <!-- Odometry source, 0 for ENCODER, 1 for WORLD, defaults to WORLD -->
    <odometrySource>1</odometrySource>

    <!-- Set to true to publish transforms for the wheel links, defaults to false -->
    <publishWheelTF>true</publishWheelTF>

    <!-- Set to true to publish transforms for the odometry, defaults to true -->
    <publishOdom>true</publishOdom>

    <!-- Set to true to publish sensor_msgs/JointState on /joint_states for the wheel joints, defaults to false -->
    <publishWheelJointState>true</publishWheelJointState>

    <!-- Set to true to swap right and left wheels, defaults to true -->
    <legacyMode>true</legacyMode>
  </plugin>

 <gazebo reference="base_footprint">
    <material>Gazebo/light_grey</material>
    <gravity>true</gravity>
 </gazebo>
  
 <gazebo reference="base_link">
    <material>Gazebo/light_grey</material>
 </gazebo>
 
 <gazebo reference="left_wheel_link">
    <material>Gazebo/dark_grey</material>
    <mu1>0.0</mu1>
    <mu2>0.0</mu2>
 </gazebo>
  
 <gazebo reference="right_wheel_link">
    <material>Gazebo/dark_grey</material>
    <mu1>0.0</mu1>
    <mu2>0.0</mu2>
  </gazebo>

</robot>
