<?xml version="1.0"?>
<robot name="holo" xmlns:xacro="http://ros.org/wiki/xacro">

  <material name="black"><color rgba="0.15 0.15 0.15 1.0"/></material>
  <material name="dark_grey"><color rgba="0.2 0.2 0.2 1.0"/></material>
  <material name="light_grey"><color rgba="0.4 0.4 0.4 1.0"/></material>

  <link name="base_footprint"></link>
  <joint name="base_link_joint" type="fixed">
    <origin xyz="0 0 0.05" rpy="0 0 0" />
    <parent link="base_footprint"/>
    <child link="base_link"/>
  </joint>
  
  <link name="base_link">
    <inertial>
      <origin
        xyz="0.000663062226349709 0.000901948709669016 0.0518310748808297"
        rpy="0 0 0" />
      <mass value="1" />
      <inertia
        ixx="0.0005"
        ixy="0.2359267438"
        ixz="3.83933411877259E-15"
        iyy="0.0005"
        iyz="3.03157454020582E-18"
        izz="0.0005" />
    </inertial>
    <visual>
      <origin xyz="0 0 0" rpy="0 0 0" />
      <geometry>
        <mesh filename="package://non_description/meshes/base_link.STL" />
      </geometry>
      <material name="light_grey"/>
    </visual>
    <collision>
      <origin xyz="0 0 0" rpy="0 0 0" />
      <geometry>
        <mesh filename="package://non_description/meshes/base_link.STL" />
      </geometry>
    </collision>
  </link>
  
  <link name="left_wheel_link">
    <inertial>
      <origin xyz="-1.11022302462516E-16 -0.0099999999999999 0" rpy="0 0 0" />
      <mass value="0.172530421663568" />

      <origin xyz="0 5.5511E-17 2.7756E-17" rpy="0 0 0" />
      <mass value="0.23316" />
      <inertia
        ixx="0.00023384"
        ixy="1.8449E-18"
        ixz="5.5653E-21"
        iyy="0.00044999"
        iyz="-2.6244E-20"
        izz="0.00023384" />
    </inertial>
    <visual>
      <origin xyz="0 0 0" rpy="0 0 0" />
      <geometry>
        <mesh filename="package://non_description/meshes/left_wheel_link.STL" />
      </geometry>
      <material name="dark_grey"/>
    </visual>
    <collision>
      <origin xyz="0 0 0" rpy="0 0 0" />
      <geometry>
        <mesh filename="package://non_description/meshes/left_wheel_link.STL" />
      </geometry>
    </collision>
</link>
  <joint name="left_wheel_joint" type="continuous">
    <origin xyz="0.00068317 0.27589 0.029895" rpy="0 0 0" />
    <parent link="base_link" />
    <child link="left_wheel_link" />
    <axis xyz="0 -1 0" />
  </joint>
  <link name="right_wheel_link">
    <inertial>
      <origin xyz="1.1102E-16 -5.5511E-17 1.3878E-17" rpy="0 0 0" />
      <mass value="0.23316" />
      <inertia
        ixx="0.00023384"
        ixy="1.8559E-18"
        ixz="-4.9188E-21"
        iyy="0.00044999"
        iyz="-2.8705E-20"
        izz="0.00023384" />
    </inertial>
    <visual>
      <origin xyz="0 0 0" rpy="0 0 0" />
      <geometry>
        <mesh filename="package://non_description/meshes/right_wheel_link.STL" />
      </geometry>
      <material name="dark_grey"/>
    </visual>
    <collision>
      <origin xyz="0 0 0" rpy="0 0 0" />
      <geometry>
        <mesh filename="package://non_description/meshes/right_wheel_link.STL" />
      </geometry>
    </collision>
  </link>
  <joint name="right_wheel_joint" type="continuous">
    <origin xyz="0.00068317 -0.27411 0.029895" rpy="0 0 0" />
    <parent link="base_link" />
    <child link="right_wheel_link" />
    <axis
      xyz="0 -1 0" />
  </joint>

  <!-- Include controller plugin for Gazebo -->
  <xacro:include filename="$(find non_description)/urdf/non.gazebo" />

</robot>
